<?xml version="1.0"?>
<robot name="simple_exaple">

  <!--Link #1-->
  <link name="base_link">
    <inertial>
        <mass value="10" />
        <inertia ixx="0.4" ixy="0.0" ixz="0.0" iyy="0.4" iyz="0.0" izz="0.2"/>
    </inertial>
    <collision>
      <geometry>
        <cylinder radius="0.05" length="0.24" />
      </geometry>
        </collision>
    <visual>
      <geometry>
        <cylinder radius="0.05" length="0.24" />
      </geometry>
    </visual>
    <ode>
      <mu>100</mu>
      <mu2>100</mu2>
      <fdir1>1 0 0</fdir1>
      <slip1>0</slip1>
      <slip2>0</slip2>
    </ode>
    <kinematic>true</kinematic>
  </link>

  <!--Link #2-->
  <link name="second_link">
    <inertial>
        <mass value="0.18" />
        <inertia ixx="0.0" ixy="0.0" ixz="0.0" iyy="0.0" iyz="0.0" izz="0.0" />
    </inertial>
    <origin rpy="0.0 0.0 0.0" xyz="0.0 0.0 0.0" />
    <collision>
      <geometry>
        <cylinder radius="0.25" length="0.05" />
      </geometry>
    </collision>
    <visual>
      <geometry>
        <cylinder radius="0.25" length="0.05" />
      </geometry>
    </visual>
    <ode>
      <mu>-dInfinity</mu>
      <mu2>-dInfinity</mu2>
      <fdir1>1 0 0</fdir1>
      <slip1>0</slip1>
      <slip2>0</slip2>
    </ode>
    <kinematic>true</kinematic>
  </link>

  <!--joint-->
  <joint name="base_to_second_joint" type="continuous">
    <parent link="base_link"/>
    <child link="second_link"/>
    <axis xyz="0 0 1"/>
    <origin xyz="0.0 0.0 0.16" rpy="0.0 0.0 0.0"/> 
  </joint>

  <!--                GAZEBO RELATED PART                             -->

  <!-- ROS Control plugin for Gazebo. This allows Gazebo and Ros to to be connected,
       and for ros to control the model in the gazebo visualization -->
  <!-- <gazebo>
    <plugin name="gazebo_ros_control" filename="libgazebo_ros_control.so">
	  <this is the namespace in the yaml file>
      <robotNamespace>/simple_model</robotNamespace>
      <-The two lines below came from: https://answers.ros.org/question/292444/gazebo_ros_control-plugin-gazeboroscontrolplugin-missing-legacymodens-defaultrobothwsim/
      <robotSimType>gazebo_ros_control/DefaultRobotHWSim</robotSimType>
      <legacyModeNS>true</legacyModeNS>
    </plugin>
  </gazebo> -->

  <gazebo>
    <plugin name="omni_steering" filename="libgazebo_ros_planar_move.so">
      <commandTopic>/table_cmd_vel</commandTopic>
      <odometryTopic>/odom</odometryTopic>
      <odometryFrame>/odom</odometryFrame>
      <odometryRate>50.0</odometryRate>
      <robotBaseFrame>base_link</robotBaseFrame>
      <publishTF>false</publishTF>
    </plugin>
  </gazebo>
  <gazebo>
    <plugin name="ros_control" filename="libgazebo_ros_control.so">
    <!--robotNamespace>/</robotNamespace-->
    <!--robotSimType>gazebo_ros_control/DefaultRobotHWSim</robotSimType-->
    </plugin>
  </gazebo>



  <!-- transmission is the ability to define the ros controller used to control the joint. -->
  <transmission name="base_to_second_trans">
    <type>transmission_interface/SimpleTransmission</type>
    <actuator name="motor1">
      <mechanicalReduction>1</mechanicalReduction>
    </actuator>
    <joint name="base_to_second_joint">
      <!--lets use a postion type interface, which is a mechanism for ros_control
          to communicate with hardware. See: https://wiki.ros.org/ros_control-->
      <hardwareInterface>hardware_interface/VelocityJointInterface</hardwareInterface>
    </joint>
  </transmission>
</robot>